Workbook

Sheet sim_driver
A1: sim_world | B1: name | C1: value | D1: explanation
A2: medicare | B2: ICC | C2: =medicare_calcs!B24 -> 0.005 | D2: bene-level resid ICC
A3: medicare | B3: sigma_y | C3: 880 | D3: mean sigma_y for multiple cpc+ runs
A4: medicare | B4: r2a | C4: =medicare_calcs!B26 -> 0.5 | D4: R-squared for resids
A5: medicare | B5: r2uv | C5: 0.15 | D5: mean of sig2v/(sig2u+sig2v) values is 0.2 across multiple iBCF runs on CPC+
A6: medicare | B6: r2trt | C6: =medicare_calcs!B28 -> 0.4 | D6: Proportion of treatment effect variance explained by measured covariates: var(taux)/(var(taux)+sig2v)
A7: medicare | B7: rho | C7: 0 | D7: Correlation between u and v.
A8: edu | B8: ICC | C8: =edu_cals!B48 -> 0.009 | D8: residual ICC
A9: edu | B9: sigma_y | C9: =edu_cals!B49 -> 0.8 | D9: mean sigma_y
A10: edu | B10: r2a | C10: =edu_cals!B50 -> 0.9 | D10: R-squared for resids
A11: edu | B11: r2uv | C11: =edu_cals!B51 -> 0.2 | D11: mean of sig2v/(sig2u+sig2v) values is 0.2 across multiple iBCF runs on CPC+
A12: edu | B12: r2trt | C12: =edu_cals!B52 -> 0.3 | D12: Proportion of treatment effect variance explained by measured covariates: var(taux)/(var(taux)+sig2v)
A13: edu | B13: rho | C13: 0 | D13: Correlation between u and v.

Sheet sim_driver_struc
A1: sim_world | B1: name | C1: value | D1: explanation | E1: change reason
A2: medicare | B2: ICC | C2: 0.0143 | D2: bene-level resid ICC | E2: Irina's runs show 110, 108, 91, 116 for sigma_u, so average is 106. For a sigma_y of 880, that implies an ICC of .0143
A3: medicare | B3: sigma_y | C3: 880 | D3: mean sigma_y for multiple cpc+ runs
A4: medicare | B4: sigma_u | C4: 106 | D4: Irina's runs show 110, 108, 91, 116 for sigma_u, so average is 106
A5: medicare | B5: sigma_v | C5: 13.25 | D5: SD(y) is about 150, so sigma_v should be about 14 (106*20/150), so 14^2/(14^2+106^2)
A6: medicare | B6: sigma_taux | C6: 21 | D6: same as what we used to have, with r2trt=.4 and sigma_v=26
A7: medicare | B7: r2a | C7: =medicare_calcs!B26 -> 0.5 | D7: R-squared for resids
A8: medicare | B8: r2uv | C8: 0.0154 | D8: mean of sig2v/(sig2u+sig2v) values is 0.2 across multiple iBCF runs on CPC+ | E8: SD(y) is about 160, so sigma_v should be about 14 (106*20/160), so 13.25^2/(13.25^2+106^2)
A9: medicare | B9: r2trt | C9: =medicare_calcs!B28 -> 0.4 | D9: Proportion of treatment effect variance explained by measured covariates: var(taux)/(var(taux)+sig2v)
A10: medicare | B10: rho | C10: 0 | D10: Correlation between u and v.
A11: edu | B11: ICC | C11: =edu_cals!B48 -> 0.009 | D11: residual ICC
A12: edu | B12: sigma_y | C12: =edu_cals!B49 -> 0.8 | D12: mean sigma_y
A13: edu | B13: r2a | C13: =edu_cals!B50 -> 0.9 | D13: R-squared for resids
A14: edu | B14: r2uv | C14: =edu_cals!B51 -> 0.2 | D14: mean of sig2v/(sig2u+sig2v) values is 0.2 across multiple iBCF runs on CPC+
A15: edu | B15: r2trt | C15: =edu_cals!B52 -> 0.3 | D15: Proportion of treatment effect variance explained by measured covariates: var(taux)/(var(taux)+sig2v)
A16: edu | B16: rho | C16: 0 | D16: Correlation between u and v.

Sheet sim_driver_rereparam
A1: sim_world | B1: name | C1: value | D1: explanation
A2: medicare | B2: sigma_y | C2: 2557 | D2: track 1 combined estimate from stan, see calibrate.R
A3: medicare | B3: sigma_u | C3: 61.3 | D3: track 1 combined estimate from stan, see calibrate.R
A4: medicare | B4: sigma_v | C4: 8.33 | D4: SD(y) is 147.22, so sigma_v should be about 14 (61.3*20/147.22)
A5: medicare | B5: sigma_taux | C5: 16.73 | D5: sd(tau_hat) across both SSP/non-SSP in track 1
A6: medicare | B6: r2a | C6: 0.33 | D6: track 1 combined var(yhat)/var(y); due to shrinking inducing a correlation between yhat and resids, this is not equal to var(y-yhat)/var(y) [0.5 instead of .33], but we should use the var(yhat) based figure to get var(y) correct

Sheet scenario_key
A1: Organization of sim study scenarios:
A2: Repeat this schema for both the medicare and edu worlds.
A5: Scenario name | B5: Description
A6: 1 | B6: Test sensitivity to rho and gamma prior settings. Use baseline DGP inputs, but vary rho from -.5 to 0.5.
A7: 2 | B7: Use baseline DGP inputs (with rho=0), and vary R2uv x R2trt grid.
A8: 3 | B8: T distribution sensitivity test.
A9: 4 | B9: Baseline inputs, no weights. (We know this will fail.)

Sheet scenarios
A1: scenario_num | B1: scenario | C1: scenario_desc | D1: world | E1: r2uv_multiplier | F1: r2trt_multiplier | G1: rho | H1: trt_eff_scenario | I1: nC | J1: nT | K1: weights | L1: uv_dist | M1: uv_dist_df | N1: r2uv_unadj | O1: r2uv_adj | P1: r2trt_unadj | Q1: r2trt_adj
A2: 1 | B2: medicare_1 | D2: medicare | E2: 0.75 | F2: 0.75 | G2: =sim_driver!$C$7 -> 0 | H2: het | I2: 2000 | J2: 1000 | K2: TRUE | L2: normal | N2: =sim_driver!$C$5 -> 0.15 | O2: =N2*E2 -> 0.1125 | P2: =sim_driver!$C$6 -> 0.4 | Q2: =P2*F2 -> 0.3
A3: 2 | B3: medicare_1 | D3: medicare | E3: 0.75 | F3: 1 | G3: =sim_driver!$C$7 -> 0 | H3: het | I3: 2000 | J3: 1000 | K3: TRUE | L3: normal | N3: =sim_driver!$C$5 -> 0.15 | O3: =N3*E3 -> 0.1125 | P3: =sim_driver!$C$6 -> 0.4 | Q3: =P3*F3 -> 0.4
A4: 3 | B4: medicare_1 | D4: medicare | E4: 0.75 | F4: 1.25 | G4: =sim_driver!$C$7 -> 0 | H4: het | I4: 2000 | J4: 1000 | K4: TRUE | L4: normal | N4: =sim_driver!$C$5 -> 0.15 | O4: =N4*E4 -> 0.1125 | P4: =sim_driver!$C$6 -> 0.4 | Q4: =P4*F4 -> 0.5
A5: 4 | B5: medicare_1 | D5: medicare | E5: 1 | F5: 0.75 | G5: =sim_driver!$C$7 -> 0 | H5: het | I5: 2000 | J5: 1000 | K5: TRUE | L5: normal | N5: =sim_driver!$C$5 -> 0.15 | O5: =N5*E5 -> 0.15 | P5: =sim_driver!$C$6 -> 0.4 | Q5: =P5*F5 -> 0.3
A6: 5 | B6: medicare_1 | D6: medicare | E6: 1 | F6: 1 | G6: =sim_driver!$C$7 -> 0 | H6: het | I6: 2000 | J6: 1000 | K6: TRUE | L6: normal | N6: =sim_driver!$C$5 -> 0.15 | O6: =N6*E6 -> 0.15 | P6: =sim_driver!$C$6 -> 0.4 | Q6: =P6*F6 -> 0.4
A7: 6 | B7: medicare_1 | D7: medicare | E7: 1 | F7: 1.25 | G7: =sim_driver!$C$7 -> 0 | H7: het | I7: 2000 | J7: 1000 | K7: TRUE | L7: normal | N7: =sim_driver!$C$5 -> 0.15 | O7: =N7*E7 -> 0.15 | P7: =sim_driver!$C$6 -> 0.4 | Q7: =P7*F7 -> 0.5
A8: 7 | B8: medicare_1 | D8: medicare | E8: 1.25 | F8: 0.75 | G8: =sim_driver!$C$7 -> 0 | H8: het | I8: 2000 | J8: 1000 | K8: TRUE | L8: normal | N8: =sim_driver!$C$5 -> 0.15 | O8: =N8*E8 -> 0.1875 | P8: =sim_driver!$C$6 -> 0.4 | Q8: =P8*F8 -> 0.3
A9: 8 | B9: medicare_1 | D9: medicare | E9: 1.25 | F9: 1 | G9: =sim_driver!$C$7 -> 0 | H9: het | I9: 2000 | J9: 1000 | K9: TRUE | L9: normal | N9: =sim_driver!$C$5 -> 0.15 | O9: =N9*E9 -> 0.1875 | P9: =sim_driver!$C$6 -> 0.4 | Q9: =P9*F9 -> 0.4
A10: 9 | B10: medicare_1 | D10: medicare | E10: 1.25 | F10: 1.25 | G10: =sim_driver!$C$7 -> 0 | H10: het | I10: 2000 | J10: 1000 | K10: TRUE | L10: normal | N10: =sim_driver!$C$5 -> 0.15 | O10: =N10*E10 -> 0.1875 | P10: =sim_driver!$C$6 -> 0.4 | Q10: =P10*F10 -> 0.5
A11: 10 | B11: medicare_2 | D11: medicare | E11: 1 | F11: 1 | G11: =sim_driver!$C$7 -> 0 | H11: homog | I11: 2000 | J11: 1000 | K11: TRUE | L11: normal | N11: =sim_driver!$C$5 -> 0.15 | O11: =N11*E11 -> 0.15 | P11: =sim_driver!$C$6 -> 0.4 | Q11: =P11*F11 -> 0.4
A12: 11 | B12: medicare_3 | D12: medicare | E12: 1 | F12: 1 | G12: 0 | H12: het | I12: 2000 | J12: 1000 | K12: TRUE | L12: normal | N12: =sim_driver!$C$5 -> 0.15 | O12: =N12*E12 -> 0.15 | P12: =sim_driver!$C$6 -> 0.4 | Q12: =P12*F12 -> 0.4
A13: 12 | B13: medicare_3 | D13: medicare | E13: 1 | F13: 1 | G13: =-sim_driver!$C$7 -> 0 | H13: het | I13: 2000 | J13: 1000 | K13: TRUE | L13: normal | N13: =sim_driver!$C$5 -> 0.15 | O13: =N13*E13 -> 0.15 | P13: =sim_driver!$C$6 -> 0.4 | Q13: =P13*F13 -> 0.4
A14: 13 | B14: medicare_4 | D14: medicare | E14: 1 | F14: 1 | G14: =sim_driver!$C$7 -> 0 | H14: het | I14: 2000 | J14: 1000 | K14: FALSE | L14: normal | N14: =sim_driver!$C$5 -> 0.15 | O14: =N14*E14 -> 0.15 | P14: =sim_driver!$C$6 -> 0.4 | Q14: =P14*F14 -> 0.4
A15: 14 | B15: medicare_5 | D15: medicare | E15: 1 | F15: 1 | G15: =sim_driver!$C$7 -> 0 | H15: het | I15: 2000 | J15: 1000 | K15: TRUE | L15: t | M15: 3 | N15: =sim_driver!$C$5 -> 0.15 | O15: =N15*E15 -> 0.15 | P15: =sim_driver!$C$6 -> 0.4 | Q15: =P15*F15 -> 0.4
A16: 1 | B16: edu_1 | D16: edu | E16: 0.75 | F16: 0.75 | G16: =sim_driver!$C$13 -> 0 | H16: het | I16: 2000 | J16: 1000 | K16: TRUE | L16: normal | N16: =sim_driver!$C$11 -> 0.2 | O16: =N16*E16 -> 0.15 | P16: =sim_driver!$C$12 -> 0.3 | Q16: =P16*F16 -> 0.225
A17: 2 | B17: edu_1 | D17: edu | E17: 0.75 | F17: 1 | G17: =sim_driver!$C$13 -> 0 | H17: het | I17: 2000 | J17: 1000 | K17: TRUE | L17: normal | N17: =sim_driver!$C$11 -> 0.2 | O17: =N17*E17 -> 0.15 | P17: =sim_driver!$C$12 -> 0.3 | Q17: =P17*F17 -> 0.3
A18: 3 | B18: edu_1 | D18: edu | E18: 0.75 | F18: 1.25 | G18: =sim_driver!$C$13 -> 0 | H18: het | I18: 2000 | J18: 1000 | K18: TRUE | L18: normal | N18: =sim_driver!$C$11 -> 0.2 | O18: =N18*E18 -> 0.15 | P18: =sim_driver!$C$12 -> 0.3 | Q18: =P18*F18 -> 0.375
A19: 4 | B19: edu_1 | D19: edu | E19: 1 | F19: 0.75 | G19: =sim_driver!$C$13 -> 0 | H19: het | I19: 2000 | J19: 1000 | K19: TRUE | L19: normal | N19: =sim_driver!$C$11 -> 0.2 | O19: =N19*E19 -> 0.2 | P19: =sim_driver!$C$12 -> 0.3 | Q19: =P19*F19 -> 0.225
A20: 5 | B20: edu_1 | D20: edu | E20: 1 | F20: 1 | G20: =sim_driver!$C$13 -> 0 | H20: het | I20: 2000 | J20: 1000 | K20: TRUE | L20: normal | N20: =sim_driver!$C$11 -> 0.2 | O20: =N20*E20 -> 0.2 | P20: =sim_driver!$C$12 -> 0.3 | Q20: =P20*F20 -> 0.3
A21: 6 | B21: edu_1 | D21: edu | E21: 1 | F21: 1.25 | G21: =sim_driver!$C$13 -> 0 | H21: het | I21: 2000 | J21: 1000 | K21: TRUE | L21: normal | N21: =sim_driver!$C$11 -> 0.2 | O21: =N21*E21 -> 0.2 | P21: =sim_driver!$C$12 -> 0.3 | Q21: =P21*F21 -> 0.375
A22: 7 | B22: edu_1 | D22: edu | E22: 1.25 | F22: 0.75 | G22: =sim_driver!$C$13 -> 0 | H22: het | I22: 2000 | J22: 1000 | K22: TRUE | L22: normal | N22: =sim_driver!$C$11 -> 0.2 | O22: =N22*E22 -> 0.25 | P22: =sim_driver!$C$12 -> 0.3 | Q22: =P22*F22 -> 0.225
A23: 8 | B23: edu_1 | D23: edu | E23: 1.25 | F23: 1 | G23: =sim_driver!$C$13 -> 0 | H23: het | I23: 2000 | J23: 1000 | K23: TRUE | L23: normal | N23: =sim_driver!$C$11 -> 0.2 | O23: =N23*E23 -> 0.25 | P23: =sim_driver!$C$12 -> 0.3 | Q23: =P23*F23 -> 0.3
A24: 9 | B24: edu_1 | D24: edu | E24: 1.25 | F24: 1.25 | G24: =sim_driver!$C$13 -> 0 | H24: het | I24: 2000 | J24: 1000 | K24: TRUE | L24: normal | N24: =sim_driver!$C$11 -> 0.2 | O24: =N24*E24 -> 0.25 | P24: =sim_driver!$C$12 -> 0.3 | Q24: =P24*F24 -> 0.375
A25: 10 | B25: edu_2 | D25: edu | E25: 1 | F25: 1 | G25: =sim_driver!$C$13 -> 0 | H25: homog | I25: 2000 | J25: 1000 | K25: TRUE | L25: normal | N25: =sim_driver!$C$11 -> 0.2 | O25: =N25*E25 -> 0.2 | P25: =sim_driver!$C$12 -> 0.3 | Q25: =P25*F25 -> 0.3
A26: 11 | B26: edu_3 | D26: edu | E26: 1 | F26: 1 | G26: 0 | H26: het | I26: 2000 | J26: 1000 | K26: TRUE | L26: normal | N26: =sim_driver!$C$11 -> 0.2 | O26: =N26*E26 -> 0.2 | P26: =sim_driver!$C$12 -> 0.3 | Q26: =P26*F26 -> 0.3
A27: 12 | B27: edu_3 | D27: edu | E27: 1 | F27: 1 | G27: =-sim_driver!$C$13 -> 0 | H27: het | I27: 2000 | J27: 1000 | K27: TRUE | L27: normal | N27: =sim_driver!$C$11 -> 0.2 | O27: =N27*E27 -> 0.2 | P27: =sim_driver!$C$12 -> 0.3 | Q27: =P27*F27 -> 0.3
A28: 13 | B28: edu_4 | D28: edu | E28: 1 | F28: 1 | G28: =sim_driver!$C$13 -> 0 | H28: het | I28: 2000 | J28: 1000 | K28: FALSE | L28: normal | N28: =sim_driver!$C$11 -> 0.2 | O28: =N28*E28 -> 0.2 | P28: =sim_driver!$C$12 -> 0.3 | Q28: =P28*F28 -> 0.3
A29: 14 | B29: edu_5 | D29: edu | E29: 1 | F29: 1 | G29: =sim_driver!$C$13 -> 0 | H29: het | I29: 2000 | J29: 1000 | K29: TRUE | L29: t | M29: 3 | N29: =sim_driver!$C$11 -> 0.2 | O29: =N29*E29 -> 0.2 | P29: =sim_driver!$C$12 -> 0.3 | Q29: =P29*F29 -> 0.3
A30: 15 | B30: medicare_1a | D30: medicare | E30: 0.75 | F30: 0.75 | G30: 0 | H30: het | I30: 2000 | J30: 1000 | K30: TRUE | L30: normal
A31: 16 | B31: medicare_1a | D31: medicare | E31: 0.75 | F31: 1 | G31: 0 | H31: het | I31: 2000 | J31: 1000 | K31: TRUE | L31: normal
A32: 17 | B32: medicare_1a | D32: medicare | E32: 0.75 | F32: 1.25 | G32: 0 | H32: het | I32: 2000 | J32: 1000 | K32: TRUE | L32: normal
A33: 18 | B33: medicare_1a | D33: medicare | E33: 1 | F33: 0.75 | G33: 0 | H33: het | I33: 2000 | J33: 1000 | K33: TRUE | L33: normal
A34: 19 | B34: medicare_1a | D34: medicare | E34: 1 | F34: 1.25 | G34: 0 | H34: het | I34: 2000 | J34: 1000 | K34: TRUE | L34: normal
A35: 20 | B35: medicare_1a | D35: medicare | E35: 1.25 | F35: 0.75 | G35: 0 | H35: het | I35: 2000 | J35: 1000 | K35: TRUE | L35: normal
A36: 21 | B36: medicare_1a | D36: medicare | E36: 1.25 | F36: 1 | G36: 0 | H36: het | I36: 2000 | J36: 1000 | K36: TRUE | L36: normal
A37: 22 | B37: medicare_1a | D37: medicare | E37: 1.25 | F37: 1.25 | G37: 0 | H37: het | I37: 2000 | J37: 1000 | K37: TRUE | L37: normal
A38: 15 | B38: edu_1a | D38: edu | E38: 0.75 | F38: 0.75 | G38: 0 | H38: het | I38: 2000 | J38: 1000 | K38: TRUE | L38: normal
A39: 16 | B39: edu_1a | D39: edu | E39: 0.75 | F39: 1 | G39: 0 | H39: het | I39: 2000 | J39: 1000 | K39: TRUE | L39: normal
A40: 17 | B40: edu_1a | D40: edu | E40: 0.75 | F40: 1.25 | G40: 0 | H40: het | I40: 2000 | J40: 1000 | K40: TRUE | L40: normal
...

Sheet medicare_calcs
A1: IRINA CPC+ and Classic iBCF fits
A2: model | B2: cpc+ t1 ssp | C2: cpc+ t1 nssp | D2: cpc+ t2 ssp | E2: cpc+ t2 nssp* | F2: classic | G2: Notes
A3: outcome | B3: expenditures | C3: expenditures | D3: expenditures | E3: expenditures | F3: ed visits | G3: Not using classic, only expenditures, to determine sim study inputs.
A4: nT | B4: 738 | C4: 635 | D4: 636 | E4: 879 | F4: ?
A5: nC | B5: 2979 | C5: 2262 | D5: 1817 | E5: 1965 | F5: ?
A6: mean practice size | B6: 575 | C6: 568 | D6: 697 | E6: 644 | F6: ? | G6: Sample sizes in sim study are drawn from quantiles of prac sizes.
A7: sigma_y | B7: 1215 | C7: 1195 | D7: 1107 | E7: 1201 | F7: 480 | G7: Bene-level sigy. Prac-level sigy obtained as sigma_y / mean practice size.
A8: sigma_u | B8: 90 | C8: 84 | D8: 76 | E8: 86 | F8: 68 | G8: Posterior mean estimate.
A9: sigma_v | B9: 35 | C9: 29 | D9: 33 | E9: 27 | F9: 22 | G9: Posterior mean estimate.
A10: rho | B10: -0.4 | C10: -0.2 | D10: -0.4 | E10: -0.2 | F10: -0.2 | G10: Posterior mean estimate.
A11: sigma_y/sigma_u | B11: 13.5 | C11: 14.3 | D11: 14.6 | E11: 14.1 | F11: 7
A12: sigma_u/sigma_v | B12: 15.5 | C12: 31.9 | D12: 15.2 | E12: 21.6 | F12: 3
A13: ICC | B13: 0.006 | C13: 0.005 | D13: 0.005 | E13: 0.005 | F13: 0.02
A14: R2_uv | B14: 0.152 | C14: 0.13 | D14: 0.17 | E14: 0.12 | G14: Proportion of idiosyncratic variance attributed to treatment: sig2v / (sig2u + sig2v)
A15: R2a | B15: 0.514 | C15: 0.464 | D15: 0.506 | E15: 0.418 | G15: Residual ICC, sig2u / (sig2y + sig2u)
A16: R2b | B16: 0.09 | C16: 0.073 | D16: 0.023 | E16: 0.323 | G16: Overall R-squared: 1-RSS/SST, where RSS = var(resids) and resids = u + v + e, and SST is var(observed y). Weighted variances. Calculated for trt obs only.
A17: tau_var | B17: 3203 | C17: 2369 | D17: 1889 | E17: 8781 | G17: Variance of taux+v.
A18: taux_var | B18: 1195 | C18: 931 | D18: 255 | E18: 7385 | G18: Variance of taux.
A19: taux_var /tau_var | B19: 0.541 | C19: 0.513 | D19: 0.254 | E19: 0.822 | G19: Ratio of var(taux) / (var(mux) + var(taux). Proportion of variability in explained-by-x's function that is explained by treatment.
A20: [taux_var /tau_var]_Z1 | B20: 0.524 | C20: 0.501 | D20: 0.248 | E20: 0.837 | G20: Ratio of var(taux) / (var(mux) + var(taux). Proportion of variability in explained-by-x's function that is explained by treatment. For treated obs only.
E21: Not converged for ~1/3 of practices
A22: BASELINE SIM STUDY VALUES
A23: Input parameter | B23: Baseline value | C23: Varies in sim? | D23: Notes
A24: ICC | B24: =ROUND(AVERAGE(B13:D13),3) -> 0.005 | C24: No | D24: Average of ICCs above. | G24: =AVERAGE(B18:D18) -> 793.66667
A25: sigma_y | B25: =ROUND(AVERAGE(B7:D7),-1) -> 1170 | C25: No | D25: Average of sigma_y above. | G25: =SQRT(G24) -> 28.17209
A26: R2a | B26: =ROUND(AVERAGE(B15:D15),1) -> 0.5 | C26: No | D26: Average of R2a above.
A27: R2uv | B27: =ROUND(AVERAGE(B14:D14),2) -> 0.15 | C27: Yes | D27: Average of R2uv above.
A28: R2trt | B28: =ROUND(AVERAGE(B20:D20),1) -> 0.4 | C28: Yes | D28: Average of (taux_var / tau_var) values above.
A29: rho | B29: =ROUND(AVERAGE(B10:D10),1) -> -0.3 | C29: Yes
A31: MULTIPLIERS AND PARAMETERS FOR SIM STUDY
A32: Input parameter | B32: Range of multipliers | C32: Effect of multiplier
A33: R2uv_multiplier | B33: .5, 1, 2, 3 | C33: 0.5 doubles the distance of the baseline value from 1; 2 halves the distance of the baseline value from 1. Ex if baseline = 0.6, a multiplier of 2 yields 0.6 + (1-0.6)*2
A34: R2trt_multiplier | B34: .5, 1, 2, 3 | C34: 0.5 doubles the distance of the baseline value from 1; 2 halves the distance of the baseline value from 1. Ex if baseline = 0.6, a multiplier of 2 yields 0.6 + (1-0.6)*2
A35: rho | B35: -.5, -.25, 0, .25, 0.5 | C35: Not data-driven; just varying it over a grid. Do this for baseline values only (at least to start).
A36: trt_eff_scenario | B36: het, homog | C36: Don't need to vary R2trt_multiplier when trt_eff_scenario='homog', because in that case all trt variability is idiosyncratic, so R2trt=0.
A44: OLD: AR3
A45: model | B45: cpc+ t1 ssp* | C45: cpc+ t1 nssp | D45: cpc+ t2 ssp* | E45: cpc+ t2 nssp | F45: classic | G45: Notes
A46: outcome | B46: expenditures | C46: expenditures | D46: expenditures | E46: expenditures | F46: ed visits | G46: Not using classic, only expenditures, to determine sim study inputs.
A47: nT | B47: 738 | C47: 635 | D47: 636 | E47: 879 | F47: ?
A48: nC | B48: 2979 | C48: 2262 | D48: 1817 | E48: 1965 | F48: ?
...

Sheet edu_cals
B1: NYSED, charter as treat | D1: MSDE, fake treatment | H1: MSDE, title1 as treatment
A2: Outcome | B2: Level | C2: Growth | D2: Level | F2: Growth | H2: Level | J2: Growth
A3: Weight | B3: Actual N | D3: Actual N | E3: Adjusted N | F3: Actual N | G3: Adjusted N | H3: Actual N | I3: Adjusted N | J3: Actual N | K3: Adjusted N
A4: Nt | B4: 164 | C4: 164 | D4: 540 | E4: 540 | F4: 540 | G4: 540 | H4: 363 | I4: 363 | J4: 363 | K4: 363
A5: Nc | B5: 2107 | C5: 2107 | D5: 601 | E5: 601 | F5: 601 | G5: 601 | H5: 778 | I5: 778 | J5: 778 | K5: 778
A6: sig_y | B6: 27.224187 | C6: 28.510661 | D6: 1.1727433 | E6: 0.7937561 | F6: 1.2275977 | G6: 0.84722174 | H6: 1.1451314 | I6: 0.81645607 | J6: 1.2120408 | K6: 0.85139549
A7: sig_u | B7: 2.5012696 | C7: 2.4267255 | D7: 0.072463794 | E7: 0.076593045 | F7: 0.080890203 | G7: 0.081687404 | H7: 0.077081919 | I7: 0.075152397 | J7: 0.081525593 | K7: 0.081373738
A8: sig_v | B8: 4.1372412 | C8: 3.8011888 | D8: 0.03711947 | E8: 0.035640985 | F8: 0.032898897 | G8: 0.032025455 | H8: 0.033570504 | I8: 0.030666909 | J8: 0.034851003 | K8: 0.030191904
A9: sig_mux | B9: 9.5978613 | C9: 1.6258834 | D9: 0.49471477 | E9: 0.49512602 | F9: 0.047961015 | G9: 0.047230433 | H9: 0.50582998 | I9: 0.51425238 | J9: 0.057241411 | K9: 0.054584719
A10: sig_taux | B10: 0.77970086 | C10: 0.81481682 | D10: 0.0088312579 | E10: 0.0093669828 | F10: 0.0086786207 | G10: 0.0084952539 | H10: 0.055571471 | I10: 0.032868952 | J10: 0.030477381 | K10: 0.023879567
A11: sig_yhatx | B11: 9.6473632 | C11: 1.6697882 | D11: 0.49739526 | E11: 0.49731324 | F11: 0.04872823 | G11: 0.048021379 | H11: 0.49772738 | I11: 0.49760211 | J11: 0.049668988 | K11: 0.048767152
A12: sig_mux_t | B12: 9.8788393 | C12: 1.7492655 | D12: 0.4954761 | E12: 0.49598976 | F12: 0.048171532 | G12: 0.047383745 | H12: 0.34297537 | I12: 0.34516572 | J12: 0.054896753 | K12: 0.052096775
A13: sig_taux_t | B13: 0.91397414 | C13: 0.71180715 | D13: 0.0088355534 | E13: 0.0094599772 | F13: 0.0086965285 | G13: 0.0085176297 | H13: 0.032237688 | I13: 0.021126109 | J13: 0.025751698 | K13: 0.020078904
A14: sig_yhatx_t | B14: 9.7854854 | C14: 1.6091892 | D14: 0.50125802 | E14: 0.50070676 | F14: 0.049540885 | G14: 0.048787351 | H14: 0.34333643 | I14: 0.34279599 | J14: 0.04407483 | K14: 0.044671957
A15: corr_mutau | B15: -0.35632185 | C15: -0.17118152 | D15: 0.50251089 | E15: 0.35251553 | F15: 0.037185492 | G15: 0.041634393 | H15: 0.031044919 | I15: -0.14521811 | J15: -0.34959544 | K15: -0.32139161
... A24: r2_b | B24: 0.0094483017 | C24: 0.20713897 | D24: 0.00054631107 | E24: 0.00061876101 | F24: 0.052723791 | G24: 0.051860088 | H24: 0.020383566 | I24: 0.006527846 | J24: 0.21930152 | K24: 0.16839497
A25: =SUBSTITUTE(A6,"sig","var") -> var_y | B25: =B6^2 -> 741.15635 | C25: =C6^2 -> 812.8578 | D25: =D6^2 -> 1.3753269 | E25: =E6^2 -> 0.63004874 | F25: =F6^2 -> 1.5069961 | G25: =G6^2 -> 0.71778467 | H25: =H6^2 -> 1.3113258 | I25: =I6^2 -> 0.66660051 | ... K25: =K6^2 -> 0.72487428
A26: =SUBSTITUTE(A7,"sig","var") -> var_u | B26: =B7^2 -> 6.2563497 | C26: =C7^2 -> 5.8889967 | D26: =D7^2 -> 0.0052510014 | E26: =E7^2 -> 0.0058664946 | F26: =F7^2 -> 0.0065432249 | G26: =G7^2 -> 0.0066728319 | H26: =H7^2 -> 0.0059416223 | I26: =I7^2 -> 0.0056478827 | ... K26: =K7^2 -> 0.0066216853
A27: =SUBSTITUTE(A8,"sig","var") -> var_v | B27: =B8^2 -> 17.116764 | C27: =C8^2 -> 14.449037 | D27: =D8^2 -> 0.001377855 | E27: =E8^2 -> 0.0012702798 | F27: =F8^2 -> 0.0010823374 | G27: =G8^2 -> 0.0010256297 | H27: =H8^2 -> 0.0011269787 | I27: =I8^2 -> 0.00094045929 | ... K27: =K8^2 -> 0.0009115511
A28: =SUBSTITUTE(A9,"sig","var") -> var_mux | B28: =B9^2 -> 92.118942 | C28: =C9^2 -> 2.6434969 | D28: =D9^2 -> 0.2447427 | E28: =E9^2 -> 0.24514978 | F28: =F9^2 -> 0.0023002589 | G28: =G9^2 -> 0.0022307138 | H28: =H9^2 -> 0.25586397 | I28: =I9^2 -> 0.26445551 | ... K28: =K9^2 -> 0.0029794915
A29: =SUBSTITUTE(A10,"sig","var") -> var_taux | B29: =B10^2 -> 0.60793344 | C29: =C10^2 -> 0.66392646 | D29: =D10^2 -> 7.7991115e-05 | E29: =E10^2 -> 8.7740367e-05 | F29: =F10^2 -> 7.5318457e-05 | G29: =G10^2 -> 7.2169339e-05 | H29: =H10^2 -> 0.0030881884 | I29: =I10^2 -> 0.001080368 | ... K29: =K10^2 -> 0.00057023372
A30: =SUBSTITUTE(A11,"sig","var") -> var_yhatx | B30: =B11^2 -> 93.071617 | C30: =C11^2 -> 2.7881925 | D30: =D11^2 -> 0.24740204 | E30: =E11^2 -> 0.24732046 | F30: =F11^2 -> 0.0023744404 | G30: =G11^2 -> 0.0023060528 | H30: =H11^2 -> 0.24773254 | I30: =I11^2 -> 0.24760786 | ... K30: =K11^2 -> 0.0023782351
A31: =SUBSTITUTE(A12,"sig","var") -> var_mux_t | B31: =B12^2 -> 97.591465 | C31: =C12^2 -> 3.0599299 | D31: =D12^2 -> 0.24549656 | E31: =E12^2 -> 0.24600584 | F31: =F12^2 -> 0.0023204965 | G31: =G12^2 -> 0.0022452193 | H31: =H12^2 -> 0.1176321 | I31: =I12^2 -> 0.11913937 | ... K31: =K12^2 -> 0.002714074
A32: =SUBSTITUTE(A13,"sig","var") -> var_taux_t | B32: =B13^2 -> 0.83534872 | C32: =C13^2 -> 0.50666942 | D32: =D13^2 -> 7.8067004e-05 | E32: =E13^2 -> 8.9491168e-05 | F32: =F13^2 -> 7.5629608e-05 | G32: =G13^2 -> 7.2550015e-05 | H32: =H13^2 -> 0.0010392686 | I32: =I13^2 -> 0.00044631246 | ... K32: =K13^2 -> 0.00040316237
A33: =SUBSTITUTE(A14,"sig","var") -> var_yhatx_t | B33: =B14^2 -> 95.755724 | C33: =C14^2 -> 2.5894898 | D33: =D14^2 -> 0.2512596 | E33: =E14^2 -> 0.25070725 | F33: =F14^2 -> 0.0024542993 | G33: =G14^2 -> 0.0023802056 | H33: =H14^2 -> 0.1178799 | I33: =I14^2 -> 0.11750909 | ... K33: =K14^2 -> 0.0019955838
A34: =SUBSTITUTE(A25,"var","share") -> share_y | B34: =B25/SUM(B$25:B$29) -> 0.86456794 | C34: =C25/SUM(C$25:C$29) -> 0.97173298 | D34: =D25/SUM(D$25:D$29) -> 0.84543079 | E34: =E25/SUM(E$25:E$29) -> 0.71399852 | F34: =F25/SUM(F$25:F$29) -> 0.99340728 | G34: =G25/SUM(G$25:G$29) -> 0.98625785 | H34: =H25/SUM(H$25:H$29) -> 0.83134921 | I34: =I25/SUM(I$25:I$29) -> 0.71011286 | ... K34: =K25/SUM(K$25:K$29) -> 0.98494075
A35: =SUBSTITUTE(A26,"var","share") -> share_u | B35: =B26/SUM(B$25:B$29) -> 0.0072981084 | C35: =C26/SUM(C$25:C$29) -> 0.0070400165 | D35: =D26/SUM(D$25:D$29) -> 0.0032278568 | E35: =E26/SUM(E$25:E$29) -> 0.0066481657 | F35: =F26/SUM(F$25:F$29) -> 0.0043132741 | G35: =G26/SUM(G$25:G$29) -> 0.0091686728 | H35: =H26/SUM(H$25:H$29) -> 0.0037668464 | I35: =I26/SUM(I$25:I$29) -> 0.0060165483 | ... K35: =K26/SUM(K$25:K$29) -> 0.0089973777
A36: =SUBSTITUTE(A27,"var","share") -> share_v | B36: =B27/SUM(B$25:B$29) -> 0.019966915 | C36: =C27/SUM(C$25:C$29) -> 0.017273139 | D36: =D27/SUM(D$25:D$29) -> 0.00084698488 | E36: =E27/SUM(E$25:E$29) -> 0.0014395361 | F36: =F27/SUM(F$25:F$29) -> 0.00071347355 | G36: =G27/SUM(G$25:G$29) -> 0.0014092463 | H36: =H27/SUM(H$25:H$29) -> 0.00071447755 | I36: =I27/SUM(I$25:I$29) -> 0.0010018478 | ... K36: =K27/SUM(K$25:K$29) -> 0.0012385925
A37: =SUBSTITUTE(A28,"var","share") -> share_mux | B37: =B28/SUM(B$25:B$29) -> 0.10745787 | C37: =C28/SUM(C$25:C$29) -> 0.0031601753 | D37: =D28/SUM(D$25:D$29) -> 0.15044643 | E37: =E28/SUM(E$25:E$29) -> 0.27781434 | F37: =F28/SUM(F$25:F$29) -> 0.0015163237 | G37: =G28/SUM(G$25:G$29) -> 0.0030650682 | H37: =H28/SUM(H$25:H$29) -> 0.16221163 | I37: =I28/SUM(I$25:I$29) -> 0.28171785 | ... K37: =K28/SUM(K$25:K$29) -> 0.0040484574
A38: =SUBSTITUTE(A29,"var","share") -> share_taux | B38: =B29/SUM(B$25:B$29) -> 0.00070916178 | C38: =C29/SUM(C$25:C$29) -> 0.00079369262 | D38: =D29/SUM(D$25:D$29) -> 4.7942123e-05 | E38: =E29/SUM(E$25:E$29) -> 9.9431184e-05 | F38: =F29/SUM(F$25:F$29) -> 4.9649699e-05 | G38: =G29/SUM(G$25:G$29) -> 9.9162854e-05 | H38: =H29/SUM(H$25:H$29) -> 0.0019578376 | I38: =I29/SUM(I$25:I$29) -> 0.0011508891 | ... K38: =K29/SUM(K$25:K$29) -> 0.00077481908
A39: =SUBSTITUTE(A30,"var","share") -> share_yhatx | B39: =B30/SUM(B$25:B$29) -> 0.10856918 | C39: =C30/SUM(C$25:C$29) -> 0.003333152 | D39: =D30/SUM(D$25:D$29) -> 0.15208116 | E39: =E30/SUM(E$25:E$29) -> 0.28027425 | F39: =F30/SUM(F$25:F$29) -> 0.0015652239 | G39: =G30/SUM(G$25:G$29) -> 0.0031685863 | H39: =H30/SUM(H$25:H$29) -> 0.15705651 | I39: =I30/SUM(I$25:I$29) -> 0.26377047 | ... K39: =K30/SUM(K$25:K$29) -> 0.0032314854
A40: =SUBSTITUTE(A31,"var","share") -> share_mux_t | B40: =B31/SUM(B$25:B$29) -> 0.11384164 | C40: =C31/SUM(C$25:C$29) -> 0.0036580012 | D40: =D31/SUM(D$25:D$29) -> 0.15090984 | E40: =E31/SUM(E$25:E$29) -> 0.27878447 | F40: =F31/SUM(F$25:F$29) -> 0.0015296643 | G40: =G31/SUM(G$25:G$29) -> 0.0030849992 | H40: =H31/SUM(H$25:H$29) -> 0.07457594 | I40: =I31/SUM(I$25:I$29) -> 0.1269162 | ... K40: =K31/SUM(K$25:K$29) -> 0.0036878147
A41: =SUBSTITUTE(A32,"var","share") -> share_taux_t | B41: =B32/SUM(B$25:B$29) -> 0.00097444449 | C41: =C32/SUM(C$25:C$29) -> 0.00060569928 | D41: =D32/SUM(D$25:D$29) -> 4.7988772e-05 | E41: =E32/SUM(E$25:E$29) -> 0.00010141527 | F41: =F32/SUM(F$25:F$29) -> 4.9854809e-05 | G41: =G32/SUM(G$25:G$29) -> 9.9685915e-05 | H41: =H32/SUM(H$25:H$29) -> 0.0006588714 | I41: =I32/SUM(I$25:I$29) -> 0.00047544551 | ... K41: =K32/SUM(K$25:K$29) -> 0.00054780679
A42: =SUBSTITUTE(A33,"var","share") -> share_yhatx_t | B42: =B33/SUM(B$25:B$29) -> 0.11170022 | C42: =C33/SUM(C$25:C$29) -> 0.0030956124 | D42: =D33/SUM(D$25:D$29) -> 0.15445245 | E42: =E33/SUM(E$25:E$29) -> 0.28411232 | F42: =F33/SUM(F$25:F$29) -> 0.0016178667 | G42: =G33/SUM(G$25:G$29) -> 0.0032704745 | H42: =H33/SUM(H$25:H$29) -> 0.074733038 | I42: =I33/SUM(I$25:I$29) -> 0.1251795 | ... K42: =K33/SUM(K$25:K$29) -> 0.0027115485
A43: var(taux)/var(tau) | B43: =B29/(B29+B27) -> 0.034298663 | C43: =C29/(C29+C27) -> 0.043930926 | D43: =D29/(D29+D27) -> 0.053570987 | E43: =E29/(E29+E27) -> 0.064609029 | F43: =F29/(F29+F27) -> 0.06506118 | G43: =G29/(G29+G27) -> 0.065740025 | H43: =H29/(H29+H27) -> 0.73263724 | I43: =I29/(I29+I27) -> 0.5346167 | ... K43: =K29/(K29+K27) -> 0.38482897
A44: treated var(taux)/var(tau) | B44: =B32/(B32+B27) -> 0.046532055 | C44: =C32/(C32+C27) -> 0.033878001 | D44: =D32/(D32+D27) -> 0.053620318 | E44: =E32/(E32+E27) -> 0.065813412 | F44: =F32/(F32+F27) -> 0.065312402 | G44: =G32/(G32+G27) -> 0.066063879 | H44: =H32/(H32+H27) -> 0.47975527 | I44: =I32/(I32+I27) -> 0.32183556 | ... K44: =K32/(K32+K27) -> 0.30665417
A46: BASELINE SIM STUDY VALUES
A47: Input parameter | B47: Baseline value | C47: Varies in sim? | D47: Notes
A48: ICC | B48: =ROUND(I20,3) -> 0.009 | C48: No | D48: Average of ICCs above.
A49: sigma_y | B49: =ROUND(I6,1) -> 0.8 | C49: No | D49: Average of sigma_y above.
...

Sheet r2_multiplier_demo
A1: Here, we show how the logic for R-squared multipliers works.
A2: If multiplier < 1, adjusted R2 = orig R2 * multiplier.
A3: If multiplier > 1, adjusted R2 = 1 - (1-orig_R2)/multiplier. Ex: multiplier of 2 cuts distance from 1 in half.
A5: Original R2 | B5: Multiplier | C5: Updated R2 | D5: Orig dist from 1 | E5: Updated dist from 1 | F5: Distance from 1 is multiplied by
A6: 0.1 | B6: 1.25 | C6: =IF($B$6<=1, A6 * $B$6, 1 - (1-A6)/$B$6) -> 0.28 | D6: =1-A6 -> 0.9 | E6: =1-C6 -> 0.72 | F6: =E6/D6 -> 0.8
A7: 0.2 | C7: =IF($B$6<=1, A7 * $B$6, 1 - (1-A7)/$B$6) -> 0.36 | D7: =1-A7 -> 0.8 | E7: =1-C7 -> 0.64 | F7: =E7/D7 -> 0.8
A8: 0.3 | C8: =IF($B$6<=1, A8 * $B$6, 1 - (1-A8)/$B$6) -> 0.44 | D8: =1-A8 -> 0.7 | E8: =1-C8 -> 0.56 | F8: =E8/D8 -> 0.8
A9: 0.4 | C9: =IF($B$6<=1, A9 * $B$6, 1 - (1-A9)/$B$6) -> 0.52 | D9: =1-A9 -> 0.6 | E9: =1-C9 -> 0.48 | F9: =E9/D9 -> 0.8
A10: 0.5 | C10: =IF($B$6<=1, A10 * $B$6, 1 - (1-A10)/$B$6) -> 0.6 | D10: =1-A10 -> 0.5 | E10: =1-C10 -> 0.4 | F10: =E10/D10 -> 0.8
A11: 0.6 | C11: =IF($B$6<=1, A11 * $B$6, 1 - (1-A11)/$B$6) -> 0.68 | D11: =1-A11 -> 0.4 | E11: =1-C11 -> 0.32 | F11: =E11/D11 -> 0.8
A12: 0.7 | C12: =IF($B$6<=1, A12 * $B$6, 1 - (1-A12)/$B$6) -> 0.76 | D12: =1-A12 -> 0.3 | E12: =1-C12 -> 0.24 | F12: =E12/D12 -> 0.8
A13: 0.8 | C13: =IF($B$6<=1, A13 * $B$6, 1 - (1-A13)/$B$6) -> 0.84 | D13: =1-A13 -> 0.2 | E13: =1-C13 -> 0.16 | F13: =E13/D13 -> 0.8
A14: 0.9 | C14: =IF($B$6<=1, A14 * $B$6, 1 - (1-A14)/$B$6) -> 0.92 | D14: =1-A14 -> 0.1 | E14: =1-C14 -> 0.08 | F14: =E14/D14 -> 0.8
A16: For our sims | C16: Orig r2 | D16: Mult | E16: Updated r2 | F16: Decr by 1/4 | G16: Orig | H16: Incr by 1/4 | I16: <- new choice, apply multiplier directly
A17: medicare | B17: =sim_driver!$B$5 -> r2uv | C17: =sim_driver!$C$5 -> 0.15 | D17: 0.75 | E17: =IF(D17<=1, C17 * D17, 1 - (1-C17)/D17) -> 0.1125 | F17: =C17*0.75 -> 0.1125 | G17: =C17 -> 0.15 | H17: =C17*1.25 -> 0.1875
A18: medicare | B18: =sim_driver!$B$6 -> r2trt | C18: =sim_driver!$C$6 -> 0.4 | D18: 0.75 | E18: =IF(D18<=1, C18 * D18, 1 - (1-C18)/D18) -> 0.3 | F18: =C18*0.75 -> 0.3 | G18: =C18 -> 0.4 | H18: =C18*1.25 -> 0.5
A19: edu | B19: =sim_driver!$B$11 -> r2uv | C19: =sim_driver!$C$11 -> 0.2 | D19: 0.75 | E19: =IF(D19<=1, C19 * D19, 1 - (1-C19)/D19) -> 0.15 | F19: =C19*0.75 -> 0.15 | G19: =C19 -> 0.2 | H19: =C19*1.25 -> 0.25
A20: edu | B20: =sim_driver!$B$12 -> r2trt | C20: =sim_driver!$C$12 -> 0.3 | D20: 0.75 | E20: =IF(D20<=1, C20 * D20, 1 - (1-C20)/D20) -> 0.225 | F20: =C20*0.75 -> 0.225 | G20: =C20 -> 0.3 | H20: =C20*1.25 -> 0.375
A21: medicare | B21: =sim_driver!$B$5 -> r2uv | C21: =sim_driver!$C$5 -> 0.15 | D21: 1 | E21: =IF(D21<=1, C21 * D21, 1 - (1-C21)/D21) -> 0.15 | F21: =C21*0.75 -> 0.1125 | G21: =C21 -> 0.15 | H21: =C21*1.25 -> 0.1875
A22: medicare | B22: =sim_driver!$B$6 -> r2trt | C22: =sim_driver!$C$6 -> 0.4 | D22: 1 | E22: =IF(D22<=1, C22 * D22, 1 - (1-C22)/D22) -> 0.4 | F22: =C22*0.75 -> 0.3 | G22: =C22 -> 0.4 | H22: =C22*1.25 -> 0.5
A23: edu | B23: =sim_driver!$B$11 -> r2uv | C23: =sim_driver!$C$11 -> 0.2 | D23: 1 | E23: =IF(D23<=1, C23 * D23, 1 - (1-C23)/D23) -> 0.2 | F23: =C23*0.75 -> 0.15 | G23: =C23 -> 0.2 | H23: =C23*1.25 -> 0.25
A24: edu | B24: =sim_driver!$B$12 -> r2trt | C24: =sim_driver!$C$12 -> 0.3 | D24: 1 | E24: =IF(D24<=1, C24 * D24, 1 - (1-C24)/D24) -> 0.3 | F24: =C24*0.75 -> 0.225 | G24: =C24 -> 0.3 | H24: =C24*1.25 -> 0.375
A25: medicare | B25: =sim_driver!$B$5 -> r2uv | C25: =sim_driver!$C$5 -> 0.15 | D25: 1.25 | E25: =IF(D25<=1, C25 * D25, 1 - (1-C25)/D25) -> 0.32 | F25: =C25*0.75 -> 0.1125 | G25: =C25 -> 0.15 | H25: =C25*1.25 -> 0.1875
A26: medicare | B26: =sim_driver!$B$6 -> r2trt | C26: =sim_driver!$C$6 -> 0.4 | D26: 1.25 | E26: =IF(D26<=1, C26 * D26, 1 - (1-C26)/D26) -> 0.52 | F26: =C26*0.75 -> 0.3 | G26: =C26 -> 0.4 | H26: =C26*1.25 -> 0.5
A27: edu | B27: =sim_driver!$B$11 -> r2uv | C27: =sim_driver!$C$11 -> 0.2 | D27: 1.25 | E27: =IF(D27<=1, C27 * D27, 1 - (1-C27)/D27) -> 0.36 | F27: =C27*0.75 -> 0.15 | G27: =C27 -> 0.2 | H27: =C27*1.25 -> 0.25
A28: edu | B28: =sim_driver!$B$12 -> r2trt | C28: =sim_driver!$C$12 -> 0.3 | D28: 1.25 | E28: =IF(D28<=1, C28 * D28, 1 - (1-C28)/D28) -> 0.44 | F28: =C28*0.75 -> 0.225 | G28: =C28 -> 0.3 | H28: =C28*1.25 -> 0.375
